<?xml version="1.0" encoding="utf-8"?>
<robot name="bbot"
	xmlns:xacro="http://www.ros.org/wiki/xacro">
	<!-- caster_wheel -->
	<link name="bbot_caster_wheel">
		<inertial>
			<origin xyz="0 1.6073E-19 0" rpy="0 0 0"/>
			<mass value="0.011207"/>
			<inertia ixx="2.1965E-07" ixy="-1.5533E-55" ixz="-1.9776E-56" iyy="2.1965E-07" iyz="-2.2674E-40" izz="2.1965E-07"/>
		</inertial>
		<visual>
			<origin xyz="0 0 0" rpy="0 0 0" />
			<geometry>
				<mesh filename="package://bbot_description/meshes/bbot_caster_wheel.STL" />
			</geometry>
			<material name="Green" />
		</visual>
		<collision>
			<origin xyz="0 0 0" rpy="0 0 0" />
			<geometry>
				<mesh filename="package://bbot_description/meshes/bbot_caster_wheel.STL" />
			</geometry>
		</collision>
	</link>
	<joint name="caster_wheel_to_base" type="continuous">
		<origin xyz="-0.078 0 -0.011" rpy="0 0 0" />
		<parent link="bbot_base" />
		<child link="bbot_caster_wheel" />
		<axis xyz="0 1 0" />
	</joint>
</robot>